<?xml version="1.0"?>
<robot xmlns:xacro="http://www.ros.org/wiki/xacro" name="fan">

<link name="world"/>
    
<!-- LINKS -->
<xacro:macro name="links" params="name joint_name joint_pose parent pose r l axis color">
    <link name="${name}">
        <inertial>
            <origin xyz="0.0 0.0 0.0" rpy="0.0 0.0 0.0"/>
            <mass value="1.0"/>
            <inertia ixx="0.0" ixy="0.0" ixz="0.0" iyy="0.0" iyz="0.0" izz="0.0"/>
        </inertial>
        <visual name="">
            <origin xyz="${pose}" rpy="0.0 0.0 0.0"/>
            <geometry>
                <cylinder radius="${r}" length="${l}"/>
            </geometry>
            <material name="">
                <color rgba="${color} 1.0"/>
                <texture filename=""/>
            </material>
        </visual>
        <collision>
            <origin xyz="0.0 0.0 0.0" rpy="0.0 0.0 0.0"/>
            <geometry>
                <cylinder radius="${r}" length="${l}"/>
            </geometry>
        </collision>
    </link>

    <joint name="${joint_name}" type="revolute">
        <origin xyz="0 0 ${joint_pose}" rpy="0.0 0.0 0.0"/>
        <parent link="${parent}"/>
        <child link="${name}"/>
        <axis xyz="${axis}"/>
        <limit lower="-1.57" upper="1.57" effort="100" velocity="1"/>
    </joint>    
</xacro:macro>

<xacro:links name="link1" joint_name="joint1" joint_pose="0.75" parent="world" pose="0 0 0" r="1.5" l="1.5" axis="0 0 1"  color="0 0 0"/>
<xacro:links name="link2" joint_name="joint2" joint_pose="0.75" parent="link1" pose="0 0 1.5" r="0.8" l="4" axis="0 1 0" color="0 1 0"/>

<gazebo>
  <plugin name="gazebo_ros_control" filename="libgazebo_ros_control.so">
    <robotNamespace>/fan</robotNamespace>
  </plugin>
</gazebo>

<transmission name="trans1">
    <type>transmission_interface/SimpleTransmission</type>
    <joint name="joint1">
        <hardwareInterface>hardware_interface/PositionJointInterface</hardwareInterface>
    </joint>
    <actuator name="servo1">
        <mechanicalReduction>1.0</mechanicalReduction>
        <hardwareInterface>hardware_interface/PositionJointInterface</hardwareInterface>
    </actuator>
</transmission>

<transmission name="trans2">
    <type>transmission_interface/SimpleTransmission</type>
    <joint name="joint2">
        <hardwareInterface>hardware_interface/PositionJointInterface</hardwareInterface>
    </joint>
    <actuator name="servo2">
        <mechanicalReduction>1.0</mechanicalReduction>
        <hardwareInterface>hardware_interface/PositionJointInterface</hardwareInterface>
    </actuator>
</transmission>
    
</robot>