<?xml version="1.0"?>
<robot xmlns:xacro="http://www.ros.org/wiki/xacro" name="urdf_assembly6">
  
<link name="world">
  
</link>
 

<xacro:macro name="link" params="colour">
  
  <link
    name="base_link">
    <inertial>
      <origin
        xyz="6.93889390390723E-18 0 0.0075"
        rpy="0 0 0" />
      <mass
        value="0.3375" />
      <inertia
        ixx="0.000639140625"
        ixy="-3.12792326762068E-20"
        ixz="-4.19450715480328E-22"
        iyy="0.000639140625"
        iyz="3.8359837309772E-20"
        izz="0.001265625" />
    </inertial>
    <visual>
      <origin
        xyz="0 0 0"
        rpy="0 0 0" />
      <geometry>
        <mesh
          filename="package://urdf_assembly6/meshes/base_link.STL" />
      </geometry>
      <material
        name="">
        <color
          rgba="${colour}" />
      </material>
    </visual>
    <collision>
      <origin
        xyz="0 0 0"
        rpy="0 0 0"/>
      <geometry>
        <mesh
          filename="package://urdf_assembly6/meshes/base_link.STL" />
      </geometry>
    </collision>
  </link>

  <gazebo reference="base_link">
      <material>Gazebo/Blue</material>
  </gazebo>
  
  <joint name="ground" type="fixed">
    <origin xyz="0.0 0.0 0.0" rpy="0.0 0.0 0.0"/>
    <parent link="world"/>
    <child link="base_link"/>
    <axis xyz="0.0 0.0 0.0"/>
    <limit lower="0.0" upper="0.0" effort="0.0" velocity="0.0"/>
  </joint>

  <link
    name="link1">
    <inertial>
      <origin
        xyz="-6.93889390390723E-18 -0.00194499362413486 0.0331894017254473"
        rpy="0 0 0" />
      <mass
        value="0.487468154605903" />
      <inertia
        ixx="0.000691366465365935"
        ixy="9.5244100849736E-20"
        ixz="3.65666639180382E-20"
        iyy="0.00100288428857242"
        iyz="-5.68942714999761E-06"
        izz="0.00103205877052672" />
    </inertial>
    <visual>
      <origin
        xyz="0 0 0"
        rpy="0 0 0" />
      <geometry>
        <mesh
          filename="package://urdf_assembly6/meshes/link1.STL" />
      </geometry>
      <material
        name="">
        <color
          rgba="0.752941176470588 0.752941176470588 0.752941176470588 1" />
      </material>
    </visual>
    <collision>
      <origin
        xyz="0 0 0"
        rpy="0 0 0" />
      <geometry>
        <mesh
          filename="package://urdf_assembly6/meshes/link1.STL" />
      </geometry>
    </collision>
  </link>

  <gazebo reference="link1">
      <material>Gazebo/Black</material>
  </gazebo>

  <joint
    name="joint1"
    type="continuous">
    <origin
      xyz="0 0 0.015"
      rpy="0 0 0" />
    <parent
      link="base_link" />
    <child
      link="link1" />
    <axis
      xyz="0 0 1" />

    <limit lower="-1.57" upper="1.57" effort="100" velocity="1" />
    <dynamics damping="0.01" friction="0.01" />
  </joint>


  <link
    name="link2">
    <inertial>
      <origin
        xyz="0.0493703892650644 0.210057354276472 -0.000171992416026251"
        rpy="0 0 0" />
      <mass
        value="0.36874215950049" />
      <inertia
        ixx="0.00102864041702426"
        ixy="-1.8042072189251E-06"
        ixz="-1.28425527515793E-05"
        iyy="0.000316825139187745"
        iyz="1.14411121620837E-07"
        izz="0.000818982430369754" />
    </inertial>
    <visual>
      <origin
        xyz="0 0 0"
        rpy="0 0 0" />
      <geometry>
        <mesh
          filename="package://urdf_assembly6/meshes/link2.STL" />
      </geometry>
      <material
        name="">
        <color
          rgba="0.752941176470588 0.752941176470588 0.752941176470588 1" />
      </material>
    </visual>
    <collision>
      <origin
        xyz="0 0 0"
        rpy="0 0 0" />
      <geometry>
        <mesh
          filename="package://urdf_assembly6/meshes/link2.STL" />
      </geometry>
    </collision>
  </link>
  <joint
    name="joint2"
    type="continuous">
    <origin
      xyz="0 -0.0075 0.080337"
      rpy="0 0 -1.5708" />
    <parent
      link="link1" />
    <child
      link="link2" />
    <axis
      xyz="-1 0 0" />

    <limit lower="-1.57" upper="1.57" effort="100" velocity="1" />
    <dynamics damping="0.01" friction="0.01" />
  </joint>
  <link
    name="link3">
    <inertial>
      <origin
        xyz="-0.0832059523638297 0.00884257156732116 -1.47722040155784E-09"
        rpy="0 0 0" />
      <mass
        value="0.186526163804662" />
      <inertia
        ixx="4.61908892080329E-05"
        ixy="5.48608693427943E-11"
        ixz="-3.3453449474086E-11"
        iyy="0.000552824400918623"
        iyz="1.52247768903167E-11"
        izz="0.000543410888228976" />
    </inertial>
    <visual>
      <origin
        xyz="0 0 0"
        rpy="0 0 0" />
      <geometry>
        <mesh
          filename="package://urdf_assembly6/meshes/link3.STL" />
      </geometry>
      <material
        name="">
        <color
          rgba="${colour}" />continu
      </material>
    </visual>
    <collision>
      <origin
        xyz="0 0 0"
        rpy="0 0 0" />
      <geometry>
        <mesh
          filename="package://urdf_assembly6/meshes/link3.STL" />
      </geometry>
    </collision>
  </link>
  <joint
    name="joint3"
    type="continuous">
    <origin
      xyz="0.00021468 0.34 0.003361"
      rpy="-0.063787 0 -1.5708" />
    <parent
      link="link2" />
    <child
      link="link3" />
    <axis
      xyz="0 1 0" />

    <limit lower="-1.57" upper="1.57" effort="100" velocity="1" />
    <dynamics damping="0.01" friction="0.01" />
  </joint>
</xacro:macro>

<xacro:link colour="0.0 0.0 1.0 1.0"/>

<gazebo>
  <plugin name="gazebo_ros_control" filename="libgazebo_ros_control.so">
    <robotNamespace>/manipulator</robotNamespace>
  </plugin>
</gazebo>


<transmission name="trans_1">
  <type>transmission_interface/SimpleTransmission</type>
  <joint name="joint1">
    <hardwareInterface>hardware_interface/EffortJointInterface</hardwareInterface>
  </joint>
  <actuator name="motor1">
    <mechanicalReduction>1.0</mechanicalReduction>
    <hardwareInterface>hardware_interface/EffortJointInterface</hardwareInterface>
  </actuator>
</transmission>

<transmission name="trans_2">
  <type>transmission_interface/SimpleTransmission</type>
  <joint name="joint2">
    <hardwareInterface>hardware_interface/EffortJointInterface</hardwareInterface>
  </joint>
  <actuator name="motor2">
    <mechanicalReduction>1.0</mechanicalReduction>
    <hardwareInterface>hardware_interface/EffortJointInterface</hardwareInterface>
  </actuator>
</transmission>

<transmission name="trans_3">
  <type>transmission_interface/SimpleTransmission</type>
  <joint name="joint3">
    <hardwareInterface>hardware_interface/EffortJointInterface</hardwareInterface>
  </joint>
  <actuator name="motor3">
    <mechanicalReduction>1.0</mechanicalReduction>
    <hardwareInterface>hardware_interface/EffortJointInterface</hardwareInterface>
  </actuator>
</transmission>


  <gazebo reference="link2">
      <material>Gazebo/Blue</material>
  </gazebo>

  <gazebo reference="link3">
      <material>Gazebo/Black</material>
  </gazebo>


</robot>